<?xml version='1.0'?>
<sdf version='1.6'>
  <model name='mini_e'>
  <!-- LINKS -->
    <link name='wingfuselage_link'>
      <pose>0 0 0.35 0 -0 0</pose>
      <inertial>
        <pose>0 0 0 0 -0 0</pose>
        <mass>8.2</mass>
        <inertia>
          <ixx>1.159</ixx>
          <ixy>0</ixy>
          <ixz>0</ixz>
          <iyy>1.2301</iyy>
          <iyz>0</iyz>
          <izz>2.3864</izz>
        </inertia>
      </inertial>
      <gravity>1</gravity>
      <velocity_decay/>
      <self_collide>0</self_collide>
      <visual name='wingfuselage_link_visual'>
        <pose>1.2 -1.2639 0.26 3.14159 -0 -3.14159</pose>
        <geometry>
          <mesh>
            <uri>model://mini_e/meshes/Fuse_Stationary.STL</uri>
            <scale>0.001 0.001 0.001</scale>
          </mesh>
        </geometry>
        <material>
          <script>
            <name>Gazebo/DarkGrey</name>
            <uri>__default__</uri>
          </script>
        </material>
      </visual>
      <collision name='fuselage_collision'>
        <pose>0.3 0 0 0 -0 0</pose>
        <geometry>
          <box>
            <size>1.8 0.128 0.12</size>
          </box>
        </geometry>
        <surface>
          <contact>
            <ode>
              <kp>100000</kp>
              <kd>1.0</kd>
              <max_vel>0.1</max_vel>
              <min_depth>0.001</min_depth>
            </ode>
          </contact>
          <friction>
            <ode/>
          </friction>
        </surface>
      </collision>
      <collision name='wing_collision'>
        <pose>-0.25 0 0 0 -0 0</pose>
        <geometry>
          <box>
            <size>0.23 2.528 0.06</size>
          </box>
        </geometry>
        <surface>
          <contact>
            <ode>
              <kp>100000</kp>
              <kd>1.0</kd>
              <max_vel>0.1</max_vel>
              <min_depth>0.001</min_depth>
            </ode>
          </contact>
          <friction>
            <ode/>
          </friction>
        </surface>
      </collision>
      <collision name='fin_collision'>
        <pose>-0.46 0 0.01 0 -0 0</pose>
        <geometry>
          <box>
            <size>0.12 0.02 0.5</size>
          </box>
        </geometry>
        <surface>
          <contact>
            <ode>
              <kp>100000</kp>
              <kd>1.0</kd>
              <max_vel>0.1</max_vel>
              <min_depth>0.001</min_depth>
            </ode>
          </contact>
          <friction>
            <ode/>
          </friction>
        </surface>
      </collision>
      <collision name='left_boom_collision'>
        <pose>0.11 0.512 -0.05 0 -0 0</pose>
        <geometry>
          <box>
            <size>1.465 0.04 0.06</size>
          </box>
        </geometry>
        <surface>
          <contact>
            <ode>
              <kp>100000</kp>
              <kd>1.0</kd>
              <max_vel>0.1</max_vel>
              <min_depth>0.001</min_depth>
            </ode>
          </contact>
          <friction>
            <ode/>
          </friction>
        </surface>
      </collision>
      <collision name='right_boom_collision'>
        <pose>0.11 -0.512 -0.05 0 -0 0</pose>
        <geometry>
          <box>
            <size>1.465 0.04 0.06</size>
          </box>
        </geometry>
        <surface>
          <contact>
            <ode>
              <kp>100000</kp>
              <kd>1.0</kd>
              <max_vel>0.1</max_vel>
              <min_depth>0.001</min_depth>
            </ode>
          </contact>
          <friction>
            <ode/>
          </friction>
        </surface>
      </collision>
    </link>

    <link name='canard'>
      <inertial>
        <mass>1e-08</mass>
        <inertia>
          <ixx>1e-06</ixx>
          <ixy>0</ixy>
          <iyy>1e-06</iyy>
          <ixz>0</ixz>
          <iyz>0</iyz>
          <izz>1e-06</izz>
        </inertia>
        <pose>-0.5 0 0 0 -0 0</pose>
      </inertial>
      <pose>0.814 0 0.293 0 -0 0</pose>
      <visual name='canard_visual'>
        <pose>0.38055 -0.4899 0.0199 3.14159 -0 -3.14159</pose>
        <geometry>
          <mesh>
            <scale>0.001 0.001 0.001</scale>
            <uri>model://mini_e/meshes/Canard.STL</uri>
          </mesh>
        </geometry>
        <material>
          <script>
            <name>Gazebo/Blue</name>
            <uri>__default__</uri>
          </script>
        </material>
      </visual>
    </link>

    <link name='left_aileron'>
      <inertial>
        <mass>1e-08</mass>
        <inertia>
          <ixx>1e-06</ixx>
          <ixy>0</ixy>
          <iyy>1e-06</iyy>
          <ixz>0</ixz>
          <iyz>0</iyz>
          <izz>1e-06</izz>
        </inertia>
        <pose>0 0 0 0 -0 0</pose>
      </inertial>
      <pose>-0.3 1.08 0.35 0 -0 0</pose>
      <visual name='left_aileron_visual'>
        <pose>1.4947 -1.0799 0.007 3.14159 -0 -3.14159</pose>
        <geometry>
          <mesh>
            <scale>0.001 0.001 0.001</scale>
            <uri>model://mini_e/meshes/aileron_Left.STL</uri>
          </mesh>
        </geometry>
        <material>
          <script>
            <name>Gazebo/Blue</name>
            <uri>__default__</uri>
          </script>
        </material>
      </visual>
    </link>

    <link name='right_aileron'>
      <inertial>
        <mass>1e-08</mass>
        <inertia>
          <ixx>1e-06</ixx>
          <ixy>0</ixy>
          <iyy>1e-06</iyy>
          <ixz>0</ixz>
          <iyz>0</iyz>
          <izz>1e-06</izz>
        </inertia>
        <pose>0 0 0 0 -0 0</pose>
      </inertial>
      <pose>-0.3 -1.08 0.35 0 0 0</pose>
      <visual name='right_aileron_visual'>
        <pose>1.4947 -0.12 0.007 3.14159 -0 -3.14159</pose>
        <geometry>
          <mesh>
            <scale>0.001 0.001 0.001</scale>
            <uri>model://mini_e/meshes/aileron_Right.STL</uri>
          </mesh>
        </geometry>
        <material>
          <script>
            <name>Gazebo/Blue</name>
            <uri>__default__</uri>
          </script>
        </material>
      </visual>
    </link>

    <link name='rudder'>
      <inertial>
        <mass>1e-08</mass>
        <inertia>
          <ixx>1e-06</ixx>
          <ixy>0</ixy>
          <iyy>1e-06</iyy>
          <ixz>0</ixz>
          <iyz>0</iyz>
          <izz>1e-06</izz>
        </inertia>
        <pose>0 0 0 0 0 0</pose>
      </inertial>
      <pose>-0.46 0 0.46 0 -0 0</pose>
      <visual name='rudder_visual'>
        <pose>1.6545 -0.0022 0.149 3.14159 -0 -3.14159</pose>
        <geometry>
          <mesh>
            <scale>0.001 0.001 0.001</scale>
            <uri>model://mini_e/meshes/rudder.STL</uri>
          </mesh>
        </geometry>
        <material>
          <script>
            <name>Gazebo/Blue</name>
            <uri>__default__</uri>
          </script>
        </material>
      </visual>
    </link>

    <link name='mini_e/imu_link'>
      <pose>0 0 0.35 0 -0 0</pose>
      <inertial>
        <pose>0 0 0 0 -0 0</pose>
        <mass>0.015</mass>
        <inertia>
          <ixx>1e-05</ixx>
          <ixy>0</ixy>
          <ixz>0</ixz>
          <iyy>1e-05</iyy>
          <iyz>0</iyz>
          <izz>1e-05</izz>
        </inertia>
      </inertial>
      <self_collide>0</self_collide>
      <enable_wind>0</enable_wind>
      <kinematic>0</kinematic>
    </link>

    <include>
      <uri>model://airspeed</uri>
      <pose>0 0 0.35 0 0 0</pose>
      <name>airspeed</name>
    </include>

    <include>
      <uri>model://gps</uri>
      <pose>0 0 0.35 0 -0 0</pose>
      <name>gps</name>
    </include>

    <link name='rotor_0'>
      <pose>0.52 -0.516 0.27 0 -0 0</pose>
      <inertial>
        <pose>0 0 0 0 -0 0</pose>
        <mass>0.005</mass>
        <inertia>
          <ixx>9.75e-07</ixx>
          <ixy>0</ixy>
          <ixz>0</ixz>
          <iyy>0.000166704</iyy>
          <iyz>0</iyz>
          <izz>0.000167604</izz>
        </inertia>
      </inertial>
      <gravity>1</gravity>
      <velocity_decay/>
      <self_collide>0</self_collide>
      <enable_wind>0</enable_wind>
      <kinematic>0</kinematic>
      <visual name='rotor_0_visual'>
        <pose>0.676 -0.02 0.044 3.14159 -0 -3.14159</pose>
        <geometry>
          <mesh>
            <scale>0.001 0.001 0.001</scale>
            <uri>model://mini_e/meshes/VTOL_Rotor_Front_Right.STL</uri>
          </mesh>
        </geometry>
        <material>
          <script>
            <name>Gazebo/Blue</name>
            <uri>__default__</uri>
          </script>
          <shader type='pixel'/>
        </material>
        <transparency>0</transparency>
        <cast_shadows>1</cast_shadows>
      </visual>
    </link>

    <link name='rotor_1'>
      <pose>-0.52 0.516 0.27 0 -0 0</pose>
      <inertial>
        <pose>0 0 0 0 -0 0</pose>
        <mass>0.005</mass>
        <inertia>
          <ixx>9.75e-07</ixx>
          <ixy>0</ixy>
          <ixz>0</ixz>
          <iyy>0.000166704</iyy>
          <iyz>0</iyz>
          <izz>0.000167604</izz>
        </inertia>
      </inertial>
      <gravity>1</gravity>
      <velocity_decay/>
      <self_collide>0</self_collide>
      <enable_wind>0</enable_wind>
      <kinematic>0</kinematic>
      <visual name='rotor_1_visual'>
        <pose>0.676 -0.02 0.044 3.14159 -0 -3.14159</pose>
        <geometry>
          <mesh>
            <scale>0.001 0.001 0.001</scale>
            <uri>model://mini_e/meshes/VTOL_Rotor_Front_Right.STL</uri>
          </mesh>
        </geometry>
        <material>
          <script>
            <name>Gazebo/Blue</name>
            <uri>__default__</uri>
          </script>
          <shader type='pixel'/>
        </material>
        <transparency>0</transparency>
        <cast_shadows>1</cast_shadows>
      </visual>
    </link>

    <link name='rotor_2'>
      <pose>0.52 0.516 0.27 0 -0 0</pose>
      <inertial>
        <pose>0 0 0 0 -0 0</pose>
        <mass>0.005</mass>
        <inertia>
          <ixx>9.75e-07</ixx>
          <ixy>0</ixy>
          <ixz>0</ixz>
          <iyy>0.000166704</iyy>
          <iyz>0</iyz>
          <izz>0.000167604</izz>
        </inertia>
      </inertial>
      <gravity>1</gravity>
      <velocity_decay/>
      <self_collide>0</self_collide>
      <enable_wind>0</enable_wind>
      <kinematic>0</kinematic>
      <visual name='rotor_2_visual'>
        <pose>0.676 -0.02 0.044 3.14159 -0 -3.14159</pose>
        <geometry>
          <mesh>
            <scale>0.001 0.001 0.001</scale>
            <uri>model://mini_e/meshes/VTOL_Rotor_Front_Right.STL</uri>
          </mesh>
        </geometry>
        <material>
          <script>
            <name>Gazebo/Blue</name>
            <uri>__default__</uri>
          </script>
          <shader type='pixel'/>
        </material>
        <transparency>0</transparency>
        <cast_shadows>1</cast_shadows>
      </visual>
    </link>

    <link name='rotor_3'>
      <pose>-0.52 -0.516 0.27 0 -0 0</pose>
      <inertial>
        <pose>0 0 0 0 -0 0</pose>
        <mass>0.005</mass>
        <inertia>
          <ixx>9.75e-07</ixx>
          <ixy>0</ixy>
          <ixz>0</ixz>
          <iyy>0.000166704</iyy>
          <iyz>0</iyz>
          <izz>0.000167604</izz>
        </inertia>
      </inertial>
      <gravity>1</gravity>
      <velocity_decay/>
      <self_collide>0</self_collide>
      <enable_wind>0</enable_wind>
      <kinematic>0</kinematic>
      <visual name='rotor_3_visual'>
        <pose>0.676 -0.02 0.044 3.14159 -0 -3.14159</pose>
        <geometry>
          <mesh>
            <scale>0.001 0.001 0.001</scale>
            <uri>model://mini_e/meshes/VTOL_Rotor_Front_Right.STL</uri>
          </mesh>
        </geometry>
        <material>
          <script>
            <name>Gazebo/Blue</name>
            <uri>__default__</uri>
          </script>
          <shader type='pixel'/>
        </material>
        <transparency>0</transparency>
        <cast_shadows>1</cast_shadows>
      </visual>
    </link>

    <link name='rotor_pusher'>
      <pose>-0.531000 0 0.317000 0 1.57 0</pose>
      <inertial>
        <pose>0 0 0 0 -0 0</pose>
        <mass>0.005</mass>
        <inertia>
          <ixx>9.7e-07</ixx>
          <ixy>0</ixy>
          <ixz>0</ixz>
          <iyy>0.0001667</iyy>
          <iyz>0</iyz>
          <izz>0.0001676</izz>
        </inertia>
      </inertial>
      <gravity>1</gravity>
      <velocity_decay/>
      <self_collide>0</self_collide>
      <enable_wind>0</enable_wind>
      <kinematic>0</kinematic>
      <visual name='rotor_pusher_visual'>
        <pose>-0.190000 -0.024500 1.725000 3.14159 1.57 -3.14159</pose>
        <geometry>
          <mesh>
            <scale>0.001 0.001 0.001</scale>
            <uri>model://mini_e/meshes/Pusher_Prop.STL</uri>
          </mesh>
        </geometry>
        <material>
          <script>
            <name>Gazebo/Blue</name>
            <uri>__default__</uri>
          </script>
          <shader type='pixel'>
            <normal_map>__default__</normal_map>
          </shader>
        </material>
        <transparency>0</transparency>
        <cast_shadows>1</cast_shadows>
      </visual>
    </link>



  <!-- JOINTS -->
    <joint name='canard_joint' type='revolute'>
      <parent>wingfuselage_link</parent>
      <child>canard</child>
      <pose>0 0 0 0 -0 0</pose>
      <axis>
        <xyz>0 -1 0</xyz>
        <limit>
          <lower>-0.10297</lower> <!-- -5.9 deg-->
          <upper>0.10123</upper> <!-- 5.8 deg-->
        </limit>
        <dynamics>
          <damping>1</damping>
        </dynamics>
      </axis>
      <physics>
        <ode>
          <implicit_spring_damper>1</implicit_spring_damper>
        </ode>
      </physics>
    </joint>

    <joint name='left_aileron_joint' type='revolute'>
      <parent>wingfuselage_link</parent>
      <child>left_aileron</child>
      <pose>0.022 0 -0.001 0 0 0</pose>
      <axis>
        <xyz>0 1 0</xyz>
        <limit>
          <lower>-0.33685</lower> <!-- -19.3 deg-->
          <upper>0.36652</upper> <!-- 21 deg-->
        </limit>
        <dynamics>
          <damping>1</damping>
        </dynamics>
      </axis>
      <physics>
        <ode>
          <implicit_spring_damper>1</implicit_spring_damper>
        </ode>
      </physics>
    </joint>

    <joint name='right_aileron_joint' type='revolute'>
      <parent>wingfuselage_link</parent>
      <child>right_aileron</child>
      <pose>0.022 0 -0.001 0 0 0</pose>
       <axis>
        <xyz>0 1 0</xyz>
        <limit>
          <lower>-0.37524</lower> <!-- -21.5 deg-->
          <upper>0.35081</upper> <!-- 20.1 deg-->
        </limit>
        <dynamics>
          <damping>1</damping>
        </dynamics>
      </axis>
      <physics>
        <ode>
          <implicit_spring_damper>1</implicit_spring_damper>
        </ode>
      </physics>
    </joint>

    <joint name='rudder_joint' type='revolute'>
      <parent>wingfuselage_link</parent>
      <child>rudder</child>
      <pose>-0.025 0 0 0 -0.21 0</pose>
      <axis>
        <xyz>-0.21 0 1</xyz>
        <use_parent_model_frame>1</use_parent_model_frame>
        <limit>
          <lower>-0.78016</lower> <!-- -44.7 deg-->
          <upper>0.8081</upper> <!-- 46.3 deg-->
        </limit>
        <dynamics>
          <damping>1.000</damping>
        </dynamics>
      </axis>
      <physics>
        <ode>
          <implicit_spring_damper>1</implicit_spring_damper>
        </ode>
      </physics>
    </joint>

    <joint name='rotor_0_joint' type='revolute'>
      <parent>wingfuselage_link</parent>
      <child>rotor_0</child>
      <axis>
        <xyz>0 0 1</xyz>
        <limit>
          <lower>-1e+16</lower>
          <upper>1e+16</upper>
        </limit>
        <dynamics>
          <spring_reference>0</spring_reference>
          <spring_stiffness>0</spring_stiffness>
        </dynamics>
        <use_parent_model_frame>1</use_parent_model_frame>
      </axis>
    </joint>

    <joint name='rotor_1_joint' type='revolute'>
      <parent>wingfuselage_link</parent>
      <child>rotor_1</child>
      <axis>
        <xyz>0 0 1</xyz>
        <limit>
          <lower>-1e+16</lower>
          <upper>1e+16</upper>
        </limit>
        <dynamics>
          <spring_reference>0</spring_reference>
          <spring_stiffness>0</spring_stiffness>
        </dynamics>
        <use_parent_model_frame>1</use_parent_model_frame>
      </axis>
    </joint>

    <joint name='rotor_2_joint' type='revolute'>
      <parent>wingfuselage_link</parent>
      <child>rotor_2</child>
      <axis>
        <xyz>0 0 1</xyz>
        <limit>
          <lower>-1e+16</lower>
          <upper>1e+16</upper>
        </limit>
        <dynamics>
          <spring_reference>0</spring_reference>
          <spring_stiffness>0</spring_stiffness>
        </dynamics>
        <use_parent_model_frame>1</use_parent_model_frame>
      </axis>
    </joint>

    <joint name='rotor_3_joint' type='revolute'>
      <parent>wingfuselage_link</parent>
      <child>rotor_3</child>
      <axis>
        <xyz>0 0 1</xyz>
        <limit>
          <lower>-1e+16</lower>
          <upper>1e+16</upper>
        </limit>
        <dynamics>
          <spring_reference>0</spring_reference>
          <spring_stiffness>0</spring_stiffness>
        </dynamics>
        <use_parent_model_frame>1</use_parent_model_frame>
      </axis>
    </joint>

    <joint name='rotor_pusher_joint' type='revolute'>
      <parent>wingfuselage_link</parent>
      <child>rotor_pusher</child>
      <axis>
        <xyz>1 0 0</xyz>
        <limit>
          <lower>-1e+16</lower>
          <upper>1e+16</upper>
        </limit>
        <dynamics>
          <spring_reference>0</spring_reference>
          <spring_stiffness>0</spring_stiffness>
        </dynamics>
        <use_parent_model_frame>1</use_parent_model_frame>
      </axis>
    </joint>

    <joint name='mini_e/imu_joint' type='revolute'>
      <parent>wingfuselage_link</parent>
      <child>mini_e/imu_link</child>
      <axis>
        <xyz>1 0 0</xyz>
        <limit>
          <lower>0</lower>
          <upper>0</upper>
          <effort>0</effort>
          <velocity>0</velocity>
        </limit>
        <dynamics>
          <spring_reference>0</spring_reference>
          <spring_stiffness>0</spring_stiffness>
        </dynamics>
        <use_parent_model_frame>1</use_parent_model_frame>
      </axis>
    </joint>

    <joint name='airspeed_joint' type='fixed'>
      <child>airspeed::link</child>
      <parent>wingfuselage_link</parent>
    </joint>

    <joint name='gps_joint' type='fixed'>
      <child>gps::link</child>
      <parent>wingfuselage_link</parent>
    </joint>



  <!-- PLUGINS -->
    <plugin name='wing_body_port_lift' filename='libLiftDragPlugin.so'>
      <a0>0.128633027</a0>
      <cla>5.798332887</cla>
      <cd0>4.5729e-2</cd0>
      <cda>6.4407e-3</cda>
      <cda2>6.7679e-4</cda2>
      <cma0>3.58e-3</cma0>
      <cma>-2.85e-2</cma>
      <cma2>-3.52e-3</cma2>
      <cma3>-7.09e-5</cma3>
      <cma4>1.73e-5</cma4>
      <alpha_stall>0.174532925</alpha_stall>
      <cla_stall>-0.270550671</cla_stall>
      <cda_stall>1.443727593</cda_stall>
      <cma_stall>-0.420287461</cma_stall>
      <cp>0 0.65 0</cp>
      <area>0.25</area>
      <air_density>1.2041</air_density>
      <forward>1 0 0</forward>
      <upward>0 0 1</upward>
      <link_name>wingfuselage_link</link_name>
      <control_joint_name>left_aileron_joint</control_joint_name>
      <control_joint_rad_to_cl>-0.790364</control_joint_rad_to_cl>
    </plugin>

    <plugin name='wing_body_stbd_lift' filename='libLiftDragPlugin.so'>
      <a0>0.128633027</a0>
      <cla>5.798332887</cla>
      <cd0>4.5729e-2</cd0>
      <cda>6.4407e-3</cda>
      <cda2>6.7679e-4</cda2>
      <cma0>3.58e-3</cma0>
      <cma>-2.85e-2</cma>
      <cma2>-3.52e-3</cma2>
      <cma3>-7.09e-5</cma3>
      <cma4>1.73e-5</cma4>
      <alpha_stall>0.174532925</alpha_stall>
      <cla_stall>-0.270550671</cla_stall>
      <cda_stall>1.443727593</cda_stall>
      <cma_stall>-0.420287461</cma_stall>
      <cp>0 -0.65 0</cp>
      <area>0.25</area>
      <air_density>1.2041</air_density>
      <forward>1 0 0</forward>
      <upward>0 0 1</upward>
      <link_name>wingfuselage_link</link_name>
      <control_joint_name>right_aileron_joint</control_joint_name>
      <control_joint_rad_to_cl>-0.790364</control_joint_rad_to_cl>
    </plugin>

    <plugin name='canard_lift' filename='libLiftDragPlugin.so'>
      <a0>0</a0>
      <cla>0</cla>
      <cd0>0</cd0>
      <cda>0</cda>
      <cda2>0</cda2>
      <cma0>0</cma0>
      <cma>0</cma>
      <cma2>0</cma2>
      <cma3>0</cma3>
      <cma4>0</cma4>
      <alpha_stall>0.3391428111</alpha_stall>
      <cla_stall>0</cla_stall>
      <cda_stall>0</cda_stall>
      <cma_stall>0</cma_stall>
      <cp>0.82173 0 0.0388</cp>
      <area>0.5</area>
      <air_density>1.2041</air_density>
      <forward>1 0 0</forward>
      <upward>0 0 1</upward>
      <link_name>wingfuselage_link</link_name>
      <control_joint_name>canard_joint</control_joint_name>
      <control_joint_rad_to_cl>0.773531</control_joint_rad_to_cl>
    </plugin>

    <plugin name='rudder_lift' filename='libLiftDragPlugin.so'>
      <a0>0.0</a0>
      <cla>0.37111</cla>
      <cd0>0</cd0>
      <cda>0</cda>
      <cda2>0</cda2>
      <cma0>0</cma0>
      <cma>0</cma>
      <cma2>0</cma2>
      <cma3>0</cma3>
      <cma4>0</cma4>
      <alpha_stall>0.3391428111</alpha_stall>
      <cla_stall>-0.37111</cla_stall>
      <cda_stall>0</cda_stall>
      <cma_stall>0</cma_stall>
      <cp>-0.432 0 0.15</cp>
      <area>0.5</area>
      <air_density>1.2041</air_density>
      <forward>1 0 0</forward>
      <upward>0 1 0</upward>
      <link_name>wingfuselage_link</link_name>
      <control_joint_name>rudder_joint</control_joint_name>
      <control_joint_rad_to_cl>0.130219</control_joint_rad_to_cl>
    </plugin>

    <plugin name='front_left_motor_model' filename='libgazebo_motor_model.so'>
      <robotNamespace/>
      <jointName>rotor_2_joint</jointName>
      <linkName>rotor_2</linkName>
      <turningDirection>cw</turningDirection>
      <timeConstantUp>0.0125</timeConstantUp>
      <timeConstantDown>0.025</timeConstantDown>
      <maxRotVelocity>1115</maxRotVelocity>
      <motorConstant>0.000031831</motorConstant>
      <momentConstant>0.015541293</momentConstant>
      <commandSubTopic>/gazebo/command/motor_speed</commandSubTopic>
      <motorNumber>2</motorNumber>
      <rotorDragCoefficient>0.000106428</rotorDragCoefficient>
      <rollingMomentCoefficient>1e-6</rollingMomentCoefficient>
      <motorSpeedPubTopic>/motor_speed/2</motorSpeedPubTopic>
      <rotorVelocitySlowdownSim>20</rotorVelocitySlowdownSim>
    </plugin>

    <plugin name='front_right_motor_model' filename='libgazebo_motor_model.so'>
      <robotNamespace/>
      <jointName>rotor_0_joint</jointName>
      <linkName>rotor_0</linkName>
      <turningDirection>ccw</turningDirection>
      <timeConstantUp>0.0125</timeConstantUp>
      <timeConstantDown>0.025</timeConstantDown>
      <maxRotVelocity>1115</maxRotVelocity>
      <motorConstant>0.000031831</motorConstant>
      <momentConstant>0.015541293</momentConstant>
      <commandSubTopic>/gazebo/command/motor_speed</commandSubTopic>
      <motorNumber>0</motorNumber>
      <rotorDragCoefficient>0.000106428</rotorDragCoefficient>
      <rollingMomentCoefficient>1e-6</rollingMomentCoefficient>
      <motorSpeedPubTopic>/motor_speed/0</motorSpeedPubTopic>
      <rotorVelocitySlowdownSim>20</rotorVelocitySlowdownSim>
    </plugin>

    <plugin name='back_left_motor_model' filename='libgazebo_motor_model.so'>
      <robotNamespace/>
      <jointName>rotor_1_joint</jointName>
      <linkName>rotor_1</linkName>
      <turningDirection>ccw</turningDirection>
      <timeConstantUp>0.0125</timeConstantUp>
      <timeConstantDown>0.025</timeConstantDown>
      <maxRotVelocity>1115</maxRotVelocity>
      <motorConstant>0.000031831</motorConstant>
      <momentConstant>0.015541293</momentConstant>
      <commandSubTopic>/gazebo/command/motor_speed</commandSubTopic>
      <motorNumber>1</motorNumber>
      <rotorDragCoefficient>0.000106428</rotorDragCoefficient>
      <rollingMomentCoefficient>1e-6</rollingMomentCoefficient>
      <motorSpeedPubTopic>/motor_speed/1</motorSpeedPubTopic>
      <rotorVelocitySlowdownSim>20</rotorVelocitySlowdownSim>
    </plugin>

    <plugin name='back_right_motor_model' filename='libgazebo_motor_model.so'>
      <robotNamespace/>
      <jointName>rotor_3_joint</jointName>
      <linkName>rotor_3</linkName>
      <turningDirection>cw</turningDirection>
      <timeConstantUp>0.0125</timeConstantUp>
      <timeConstantDown>0.025</timeConstantDown>
      <maxRotVelocity>1115</maxRotVelocity>
      <motorConstant>0.000031831</motorConstant>
      <momentConstant>0.015541293</momentConstant>
      <commandSubTopic>/gazebo/command/motor_speed</commandSubTopic>
      <motorNumber>3</motorNumber>
      <rotorDragCoefficient>0.000106428</rotorDragCoefficient>
      <rollingMomentCoefficient>1e-6</rollingMomentCoefficient>
      <motorSpeedPubTopic>/motor_speed/3</motorSpeedPubTopic>
      <rotorVelocitySlowdownSim>20</rotorVelocitySlowdownSim>
    </plugin>

    <plugin name='pusher' filename='libgazebo_motor_model.so'>
      <robotNamespace/>
      <jointName>rotor_pusher_joint</jointName>
      <linkName>rotor_pusher</linkName>
      <turningDirection>cw</turningDirection>
      <timeConstantUp>0.0125</timeConstantUp>
      <timeConstantDown>0.025</timeConstantDown>
      <maxRotVelocity>930</maxRotVelocity>
      <motorConstant>0.000039962</motorConstant>
      <momentConstant>0.032314417</momentConstant>
      <commandSubTopic>/gazebo/command/motor_speed</commandSubTopic>
      <motorNumber>4</motorNumber>
      <rotorDragCoefficient>0.000106428</rotorDragCoefficient>
      <rollingMomentCoefficient>1e-6</rollingMomentCoefficient>
      <motorSpeedPubTopic>/motor_speed/4</motorSpeedPubTopic>
      <rotorVelocitySlowdownSim>20</rotorVelocitySlowdownSim>
    </plugin>

    <plugin name='gazebo_imu_plugin' filename='libgazebo_imu_plugin.so'>
      <robotNamespace/>
      <linkName>mini_e/imu_link</linkName>
      <imuTopic>/imu</imuTopic>
      <gyroscopeNoiseDensity>0.0003394</gyroscopeNoiseDensity>
      <gyroscopeRandomWalk>3.8785e-05</gyroscopeRandomWalk>
      <gyroscopeBiasCorrelationTime>1000.0</gyroscopeBiasCorrelationTime>
      <gyroscopeTurnOnBiasSigma>0.0087</gyroscopeTurnOnBiasSigma>
      <accelerometerNoiseDensity>0.004</accelerometerNoiseDensity>
      <accelerometerRandomWalk>0.006</accelerometerRandomWalk>
      <accelerometerBiasCorrelationTime>300.0</accelerometerBiasCorrelationTime>
      <accelerometerTurnOnBiasSigma>0.196</accelerometerTurnOnBiasSigma>
    </plugin>

    <plugin name='groundtruth_plugin' filename='libgazebo_groundtruth_plugin.so'>
      <robotNamespace/>
    </plugin>

    <plugin name='magnetometer_plugin' filename='libgazebo_magnetometer_plugin.so'>
      <robotNamespace/>
      <pubRate>100</pubRate>
      <noiseDensity>0.0004</noiseDensity>
      <randomWalk>6.4e-06</randomWalk>
      <biasCorrelationTime>600</biasCorrelationTime>
      <magTopic>/mag</magTopic>
    </plugin>

    <plugin name='barometer_plugin' filename='libgazebo_barometer_plugin.so'>
      <robotNamespace/>
      <pubRate>50</pubRate>
      <baroTopic>/baro</baroTopic>
    </plugin>

    <plugin name='mavlink_interface' filename='libgazebo_mavlink_interface.so'>
      <robotNamespace></robotNamespace>
      <imuSubTopic>/imu</imuSubTopic>
      <magSubTopic>/mag</magSubTopic>
      <baroSubTopic>/baro</baroSubTopic>
      <mavlink_addr>INADDR_ANY</mavlink_addr>
      <mavlink_tcp_port>{{ mavlink_tcp_port }}</mavlink_tcp_port>
      <mavlink_udp_port>{{ mavlink_udp_port }}</mavlink_udp_port>
      <serialEnabled>{{ serial_enabled }}</serialEnabled>
      <serialDevice>{{ serial_device }}</serialDevice>
      <baudRate>{{ serial_baudrate }}</baudRate>
      <qgc_addr>INADDR_ANY</qgc_addr>
      <qgc_udp_port>14550</qgc_udp_port>
      <sdk_addr>INADDR_ANY</sdk_addr>
      <sdk_udp_port>14540</sdk_udp_port>
      <hil_mode>{{ hil_mode }}</hil_mode>
      <hil_state_level>false</hil_state_level>
      <enable_lockstep>true</enable_lockstep>
      <use_tcp>true</use_tcp>
      <motorSpeedCommandPubTopic>/gazebo/command/motor_speed</motorSpeedCommandPubTopic>
      <control_channels>
        <channel name="rotor0">
          <input_index>0</input_index>
          <input_offset>0</input_offset>
          <input_scaling>1115</input_scaling>
          <zero_position_disarmed>0</zero_position_disarmed>
          <zero_position_armed>0</zero_position_armed>
          <joint_control_type>velocity</joint_control_type>
          <joint_name>rotor_0_joint</joint_name>
        </channel>
        <channel name="rotor1">
          <input_index>1</input_index>
          <input_offset>0</input_offset>
          <input_scaling>1115</input_scaling>
          <zero_position_disarmed>0</zero_position_disarmed>
          <zero_position_armed>0</zero_position_armed>
          <joint_control_type>velocity</joint_control_type>
          <joint_name>rotor_1_joint</joint_name>
        </channel>
        <channel name="rotor2">
          <input_index>2</input_index>
          <input_offset>0</input_offset>
          <input_scaling>1115</input_scaling>
          <zero_position_disarmed>0</zero_position_disarmed>
          <zero_position_armed>0</zero_position_armed>
          <joint_control_type>velocity</joint_control_type>
          <joint_name>rotor_2_joint</joint_name>
        </channel>
        <channel name="rotor3">
          <input_index>3</input_index>
          <input_offset>0</input_offset>
          <input_scaling>1115</input_scaling>
          <zero_position_disarmed>0</zero_position_disarmed>
          <zero_position_armed>0</zero_position_armed>
          <joint_control_type>velocity</joint_control_type>
          <joint_name>rotor_3_joint</joint_name>
        </channel>
        <channel name="rotor_pusher">
          <input_index>4</input_index>
          <input_offset>0</input_offset>
          <input_scaling>930</input_scaling>
          <zero_position_disarmed>0</zero_position_disarmed>
          <zero_position_armed>0</zero_position_armed>
          <joint_control_type>velocity</joint_control_type>
          <joint_name>rotor_pusher_joint</joint_name>
        </channel>
        <channel name="left_aileron">
          <input_index>5</input_index>
          <input_offset>0</input_offset>
          <input_scaling>0.349</input_scaling>
          <zero_position_disarmed>0</zero_position_disarmed>
          <zero_position_armed>0</zero_position_armed>
          <joint_control_type>position_kinematic</joint_control_type>
          <joint_name>left_aileron_joint</joint_name>
        </channel>
        <channel name="right_aileron">
          <input_index>6</input_index>
          <input_offset>0</input_offset>
          <input_scaling>0.349</input_scaling>
          <zero_position_disarmed>0</zero_position_disarmed>
          <zero_position_armed>0</zero_position_armed>
          <joint_control_type>position_kinematic</joint_control_type>
          <joint_name>right_aileron_joint</joint_name>
        </channel>
        <channel name="canard">
          <input_index>7</input_index>
          <input_offset>0</input_offset>
          <input_scaling>0.10297</input_scaling>
          <zero_position_disarmed>0</zero_position_disarmed>
          <zero_position_armed>0</zero_position_armed>
          <joint_control_type>position_kinematic</joint_control_type>
          <joint_name>canard_joint</joint_name>
        </channel>
        <channel name="rudder">
          <input_index>8</input_index>
          <input_offset>0</input_offset>
          <input_scaling>0.7854</input_scaling>
          <zero_position_disarmed>0</zero_position_disarmed>
          <zero_position_armed>0</zero_position_armed>
          <joint_control_type>position_kinematic</joint_control_type>
          <joint_name>rudder_joint</joint_name>
        </channel>
      </control_channels>
    </plugin>
    <static>0</static>
  </model>
</sdf>
